<?xml version="1.0"?>
<robot xmlns:xacro="http://www.ros.org/wiki/xacro" >
    
    <xacro:include filename="inertial_macros.xacro" />

    <material name="white">
        <color rgba="1 1 1 1" />
    </material>

    <material name="orange">
        <color rgba="1 0.3 0.1 1"/>
    </material>

    <material name="blue">
        <color rgba="0.2 0.2 1 1"/>
    </material>

    <material name="black">
        <color rgba="0 0 0 1"/>
    </material>

    <material name="red">
        <color rgba="1 0 0 1"/>
    </material>

    <!-- BASE LINK -->
    <joint name="chassis_joint" type="fixed">
        <parent link="base_link"/>
        <child link="chassis"/>
        <origin xyz="0 0 0.05"/>    
    </joint>

    <link name="chassis">
        <visual>
            <origin xyz="0 0 0.05" rpy="0 0 0"/>
            <geometry>
                <box size="0.5 0.3 0.2"/>
            </geometry>
            <material name="white"/>
        </visual>
        <collision>
            <origin xyz="0 0 0.05" rpy="0 0 0"/>
            <geometry>
                <box size="0.5 0.3 0.2"/>
            </geometry>
        </collision>
            <!-- ... visual and collision here ... -->
            <xacro:inertial_box mass="0.5" x="0.5" y="0.3" z="0.2">
                <origin xyz="0 0 0.05" rpy="0 0 0"/>
            </xacro:inertial_box>
    </link>

    <link name="base_link">

    </link>

    <!-- LEFT FRONT WHEEL -->
    <joint name="left_front_wheel_joint" type="continuous">
        <parent link="base_link"/>
        <child link="left_front_wheel"/>
        <origin xyz="0.15 -0.1 0" rpy="-${pi/2} 0 0"/>
        <axis xyz="0 0 1"/>
    </joint>

    <link name="left_front_wheel">
        <visual>
            <geometry>
                <cylinder length="0.04" radius="0.05" />
            </geometry>
            <material name="orange"/>
        </visual>
            <!-- ... visual and collision here ... -->
            <xacro:inertial_cylinder mass="0.1" length="0.05" radius="0.05">
                <origin xyz="0 0 0" rpy="0 0 0"/>
            </xacro:inertial_cylinder>
        <collision>
            <origin xyz="0.15 -0.1 0" rpy="-${pi/2} 0 0"/>
            <geometry>
                <cylinder length="0.04" radius="0.05" />
            </geometry>
        </collision>
    </link>

    <!-- LEFT BACK WHEEL -->
    <joint name="left_back_wheel_joint" type="fixed">
        <parent link="base_link"/>
        <child link="left_back_wheel"/>
        <origin xyz="-0.15 -0.1 0" rpy="-${pi/2} 0 0"/>
        <axis xyz="0 0 1"/>
    </joint>

    <link name="left_back_wheel">
        <visual>
            <geometry>
                <cylinder length="0.04" radius="0.05" />
            </geometry>
            <material name="blue"/>
        </visual>
            <!-- ... visual and collision here ... -->
            <xacro:inertial_cylinder mass="0.1" length="0.05" radius="0.05">
                <origin xyz="0 0 0" rpy="0 0 0"/>
            </xacro:inertial_cylinder>
        <collision>
            <origin xyz="-0.15 -0.1 0" rpy="-${pi/2} 0 0"/>
            <geometry>
                <cylinder length="0.04" radius="0.05" />
            </geometry>
        </collision>
    </link>

    <!-- RIGHT FRONT WHEEL -->
    <joint name="right_front_wheel_joint" type="continuous">
        <parent link="base_link"/>
        <child link="right_front_wheel"/>
        <origin xyz="0.15 0.1 0" rpy="${pi/2} 0 0"/>
        <axis xyz="0 0 -1"/>
    </joint>

    <link name="right_front_wheel">
        <visual>
            <geometry>
                <cylinder length="0.04" radius="0.05" />
            </geometry>
            <material name="red"/>
        </visual>
            <!-- ... visual and collision here ... -->
            <xacro:inertial_cylinder mass="0.1" length="0.05" radius="0.05">
                <origin xyz="0 0 0" rpy="0 0 0"/>
            </xacro:inertial_cylinder>
         <collision>
            <origin xyz="0.15 0.1 0" rpy="-${pi/2} 0 0"/>
            <geometry>
                <cylinder length="0.04" radius="0.05" />
            </geometry>
        </collision>       
    </link>

    <!-- RIGHT BACK WHEEL -->
    <joint name="right_back_wheel_joint" type="fixed">
        <parent link="base_link"/>
        <child link="right_back_wheel"/>
        <origin xyz="-0.15 0.1 0" rpy="${pi/2} 0 0"/>
        <axis xyz="0 0 -1"/>
    </joint>

    <link name="right_back_wheel">
        <visual>
            <geometry>
                <cylinder length="0.04" radius="0.05" />
            </geometry>
            <material name="black"/>
        </visual>
            <!-- ... visual and collision here ... -->
            <xacro:inertial_cylinder mass="0.1" length="0.05" radius="0.05">
                <origin xyz="0 0 0" rpy="0 0 0"/>
            </xacro:inertial_cylinder>
        <collision>
            <origin xyz="-0.15 0.1 0" rpy="-${pi/2} 0 0"/>
            <geometry>
                <cylinder length="0.04" radius="0.05" />
            </geometry>
        </collision>
    </link>

</robot>
