<?xml version="1.0"?>
<robot xmlns:xacro="http://www.ros.org/wiki/xacro" >

<material name="white">
        <color rgba="1 1 1 1" />
    </material>

    <material name="orange">
        <color rgba="1 0.3 0.1 1"/>
    </material>

    <material name="blue">
        <color rgba="0.2 0.2 1 1"/>
    </material>

    <material name="black">
        <color rgba="0 0 0 1"/>
    </material>

    <material name="red">
        <color rgba="1 0 0 1"/>
    </material>
    
    <material name="green">
        <color rgba="0 1 0 1" />
    </material>

    <material name="gray">
        <color rgba="0.5 0.5 0.5 1" />
    </material>

    <material name="pink">
        <color rgba="1 0.4 0.7 1" />
    </material>

    <material name="cyan" >
        <color rgba="0.0 1.0 1.0 1.0" />
    </material>

    <material name="yellow" >
        <color rgba="1 1 0.6 1" />
    </material>

    <!-- BASE LINK -->
    <link name="base_link">

    </link>

    <!-- chassis -->

    <joint name="chassis_joint" type="fixed">
        <parent link="base_link"/>
        <child link="chassis"/>
        <origin xyz="0 0 0.1"/>    
    </joint>

    <link name="chassis">
        <visual>
            <origin xyz="0 0 0.1" rpy="0 0 0"/>
            <geometry>
                <box size="0.6 0.455 0.2"/>
            </geometry>
            <material name="yellow"/>
        </visual>
        <collision>
            <origin xyz="0 0 0.1" rpy="0 0 0"/>
            <geometry>
                <box size="0.6 0.455 0.2"/>
            </geometry> 
        </collision>
            <!-- ... visual and collision here ... -->
        <xacro:inertial_box mass="10" x="0.6" y="0.455" z="0.2">
            <origin xyz="0 0 0.1" rpy="0 0 0"/>
        </xacro:inertial_box>
    </link>

    <gazebo reference="chassis">
        <material>Gazebo/Yellow</material>
    </gazebo>


    <!-- TOP CURVE -->
   <joint name="top_curve_joint" type="fixed">
        <parent link="chassis"/>
        <child link="top_curve"/>
        <origin xyz="-0.1 0 0.2" rpy="-${pi/2} 0 0"/>
        <axis xyz="0 0 1"/>    
    </joint>

   <link name="top_curve">
        <visual>
            <geometry>
                <cylinder length="0.455" radius="0.2"/> 
            </geometry>
            <material name="yellow"/>
        </visual>
        <collision>
            <origin xyz="-0.1 0 0.2" rpy="-${pi/2} 0 0"/>
            <geometry>
                <cylinder length="0.455" radius="0.2"/> 
            </geometry> 
        </collision>
            <!-- ... visual and collision here ... -->
        <xacro:inertial_cylinder mass="0.5" length="0.455" radius="0.2">
            <origin xyz="0 0 0.2" rpy="0 0 0"/>
        </xacro:inertial_cylinder>
    </link>

    <gazebo reference="top_curve">
        <material>Gazebo/Yellow</material>
    </gazebo>


    <!-- LEFT FRONT WHEEL -->
    <joint name="left_front_wheel_joint" type="continuous">
        <parent link="base_link"/>
        <child link="left_front_wheel"/>
        <origin xyz="0.18 -0.22 0.05" rpy="-${pi/2} 0 0"/>
        <axis xyz="0 0 1"/>
    </joint>

    <link name="left_front_wheel">
        <visual>
            <geometry>
                <cylinder length="0.08" radius="0.1" />
            </geometry>
            <material name="gray"/>
        </visual>
        <collision>     
            <origin xyz="0.18 -0.22 0.05" rpy="-${pi/2} 0 0"/>
            <geometry>
                <cylinder length="0.08" radius="0.1" />
            </geometry>
        </collision>
        <!-- ... visual and collision here ... -->
        <xacro:inertial_cylinder mass="0.1" length="0.08" radius="0.1">
            <origin xyz="0 0 0.05" rpy="0 0 0"/>
        </xacro:inertial_cylinder>
    </link>

    <gazebo reference="left_front_wheel">
        <material>Gazebo/Gray</material>
    </gazebo>

    <!-- LEFT BACK WHEEL -->
    <joint name="left_back_wheel_joint" type="continuous">
        <parent link="base_link"/>
        <child link="left_back_wheel"/>
        <origin xyz="-0.18 -0.22 0.05" rpy="-${pi/2} 0 0"/>
        <axis xyz="0 0 1"/>
    </joint>

    <link name="left_back_wheel">
        <visual>
            <geometry>
                <cylinder length="0.08" radius="0.1" />
            </geometry>
            <material name="gray"/>
        </visual>
            <!-- ... visual and collision here ... -->
        <collision>
            <origin xyz="-0.18 -0.22 0.05" rpy="-${pi/2} 0 0"/>
            <geometry>
                <cylinder length="0.08" radius="0.1" />
            </geometry>
        </collision>
        <xacro:inertial_cylinder mass="0.1" length="0.08" radius="0.1">
            <origin xyz="0 0 0.05" rpy="0 0 0"/>
        </xacro:inertial_cylinder>
    </link>

    <gazebo reference="left_back_wheel">
        <material>Gazebo/Gray</material>
    </gazebo>

    <!-- RIGHT FRONT WHEEL -->
    <joint name="right_front_wheel_joint" type="continuous">
        <parent link="base_link"/>
        <child link="right_front_wheel"/>
        <origin xyz="0.18 0.22 0.05" rpy="${pi/2} 0 0"/>
        <axis xyz="0 0 1"/>
    </joint>

    <link name="right_front_wheel">
        <visual>
            <geometry>
                <cylinder length="0.08" radius="0.1" />
            </geometry>
            <material name="gray"/>
        </visual>
            <!-- ... visual and collision here ... -->
         <collision>
            <origin xyz="0.18 0.22 0.05" rpy="-${pi/2} 0 0"/>
            <geometry>
                <cylinder length="0.08" radius="0.1" />
            </geometry>
        </collision>
        <xacro:inertial_cylinder mass="0.1" length="0.08" radius="0.1">
            <origin xyz="0 0 0.05" rpy="0 0 0"/>
        </xacro:inertial_cylinder>       
    </link>

    <gazebo reference="right_front_wheel">
        <material>Gazebo/Gray</material>
    </gazebo>

    <!-- RIGHT BACK WHEEL -->
    <joint name="right_back_wheel_joint" type="continuous">
        <parent link="base_link"/>
        <child link="right_back_wheel"/>
        <origin xyz="-0.18 0.22 0.05" rpy="${pi/2} 0 0"/>
        <axis xyz="0 0 1"/>
    </joint>

    <link name="right_back_wheel">
        <visual>
            <geometry>
                <cylinder length="0.08" radius="0.1" />
            </geometry>
            <material name="gray"/>
        </visual>
            <!-- ... visual and collision here ... -->
        <collision>
            <origin xyz="-0.18 0.22 0.05" rpy="-${pi/2} 0 0"/>
            <geometry>
                <cylinder length="0.08" radius="0.1" />
            </geometry>
        </collision>
        <xacro:inertial_cylinder mass="0.1" length="0.08" radius="0.1">
            <origin xyz="0 0 0.05" rpy="0 0 0"/>
        </xacro:inertial_cylinder>
    </link>

    <gazebo reference="right_back_wheel">
        <material>Gazebo/Gray</material>
    </gazebo>

</robot>